Workbook

Sheet isyatirim
A1: Sanayi şirketlerinde en son açıklanmış yıl sonu rakamları enflasyon düzeltmesiyle son finansal döneme çekilmektedir. | B1: 2026/3 | C1: 2025/12 | D1: 2025/9 | E1: 2025/6 | F1: 2025/3 | G1: 2024/12 | H1: 2024/9 | I1: 2024/6 | J1: 2024/3 | K1: 2023/12 | L1: 2023/9 | M1: 2023/6 | N1: 2023/3 | O1: 2022/12 | P1: 2022/9 | Q1: 2022/6 | R1: 2022/3 | S1: 2021/12 | T1: 2021/9 | U1: 2021/6 | V1: 2021/3 | W1: 2020/12 | X1: 2020/9 | Y1: 2020/6 | Z1: 2020/3
A2: Bilanço
A3: Dönen Varlıklar | B3: 257051476000 | C3: 275790750346 | D3: 229845844000 | E3: 212417591000 | F3: 190897349000 | G3: 239344848455 | H3: 179786255000 | I3: 152319925000 | J3: 152185324000 | K3: 134518116000 | L3: 121635164000 | M3: 106012576000 | N3: 84645089000 | O3: 80656225000 | P3: 85462002000 | Q3: 80755626000 | R3: 67780864000 | S3: 65693526000 | T3: 40156967000 | U3: 33396936000 | V3: 27112480000 | W3: 28507242000 | X3: 31035758000 | Y3: 29162120000 | Z3: 26708242000
A4: Nakit ve Nakit Benzerleri | B4: 123933482000 | C4: 127070780476 | D4: 97706053000 | E4: 83896762000 | F4: 70389406000 | G4: 72331091723 | H4: 47837669000 | I4: 28432001000 | J4: 24430907000 | K4: 24072967000 | L4: 19546494000 | M4: 15329917000 | N4: 20082113000 | O4: 15186458000 | P4: 11377729000 | Q4: 12002172000 | R4: 15798897000 | S4: 23189668000 | T4: 12995238000 | U4: 10286783000 | V4: 8184237000 | W4: 13542177000 | X4: 15376711000 | Y4: 14482916000 | Z4: 12836167000
A5: Finansal Yatırımlar | B5: 222299000 | C5: 0 | D5: 0 | E5: 0 | F5: 1605093000 | G5: 2076225899 | H5: 4521202000 | I5: 1214981000 | J5: 1829647000 | K5: 1737825000 | L5: 1686508000 | M5: 1538107000 | N5: 1329744000 | O5: 700187000 | P5: 374040000 | Q5: 453688000 | R5: 383374000 | S5: 9862000 | T5: 9714000 | U5: 9706000 | V5: 9718000 | W5: 39048000 | X5: 213883000 | Y5: 182717000 | Z5: 171036000
A6: Ticari Alacaklar | B6: 27036031000 | C6: 30203469998 | D6: 26581146000 | E6: 26111297000 | F6: 25744868000 | G6: 34639233322 | H6: 23547947000 | I6: 24515854000 | J6: 23048572000 | K6: 20353161000 | L6: 18015018000 | M6: 15674915000 | N6: 12454544000 | O6: 15602149000 | P6: 17412683000 | Q6: 15568911000 | R6: 12748393000 | S6: 11413658000 | T6: 6905911000 | U6: 5412635000 | V6: 4907414000 | W6: 3827829000 | X6: 3713455000 | Y6: 3450524000 | Z6: 3294601000
A7: Finans Sektörü Faaliyetlerinden Alacaklar | B7: 0 | C7: 0 | D7: 0 | E7: 0 | F7: 0 | G7: 0 | H7: 0 | I7: 0 | J7: 0 | K7: 0 | L7: 0 | M7: 0 | N7: 0 | O7: 0 | P7: 0 | Q7: 0 | R7: 0 | S7: 0 | T7: 0 | U7: 0 | V7: 0 | W7: 0 | X7: 0 | Y7: 0 | Z7: 0
A8: Diğer Alacaklar | B8: 282679000 | C8: 303915540 | D8: 267627000 | E8: 435250000 | F8: 229061000 | G8: 256123564 | H8: 162633000 | I8: 163148000 | J8: 137821000 | K8: 127846000 | L8: 123528000 | M8: 104038000 | N8: 77134000 | O8: 61164000 | P8: 61990000 | Q8: 61322000 | R8: 52988000 | S8: 51981000 | T8: 52211000 | U8: 52473000 | V8: 47877000 | W8: 46520000 | X8: 46099000 | Y8: 159264000 | Z8: 29573000
A9: Müşteri Sözleşmelerinden Doğan Varlıklar | B9: 0 | C9: 0 | D9: 0 | E9: 0 | F9: 0 | G9: 0 | H9: 0 | I9: 0 | J9: 0 | K9: 0 | L9: 0 | M9: 0 | N9: 0 | O9: 0 | P9: 0 | Q9: 0 | R9: 0 | S9: 0 | T9: 0 | U9: 0 | V9: 0 | W9: 0 | X9: 0 | Y9: 0 | Z9: 0
A10: Stoklar | B10: 88430422000 | C10: 98360024069 | D10: 87652119000 | E10: 84456730000 | F10: 76186420000 | G10: 103093936948 | H10: 86431444000 | I10: 82550430000 | J10: 78137696000 | K10: 67276704000 | L10: 62672512000 | M10: 60631392000 | N10: 44443601000 | O10: 44152408000 | P10: 52315306000 | Q10: 49353053000 | R10: 36456226000 | S10: 28960197000 | T10: 18550243000 | U10: 16189514000 | V10: 12792999000 | W10: 10106678000 | X10: 10637118000 | Y10: 9725335000 | Z10: 9353864000
A11: Canlı Varlıklar | B11: 0 | C11: 0 | D11: 0 | E11: 0 | F11: 0 | G11: 0 | H11: 0 | I11: 0 | J11: 0 | K11: 0 | L11: 0 | M11: 0 | N11: 0 | O11: 0 | P11: 0 | Q11: 0 | R11: 0 | S11: 0 | T11: 0 | U11: 0 | V11: 0 | W11: 0 | X11: 0 | Y11: 0 | Z11: 0
A12: Diğer Dönen Varlıklar | B12: 17146563000 | C12: 19852560263 | D12: 17638899000 | E12: 17517552000 | F12: 16742501000 | G12: 26948236998 | H12: 17285360000 | I12: 15443511000 | J12: 24600681000 | K12: 20949613000 | L12: 19591104000 | M12: 12734207000 | N12: 6257953000 | O12: 4953859000 | P12: 3920254000 | Q12: 3316480000 | R12: 2340986000 | S12: 2068160000 | T12: 1643650000 | U12: 1445825000 | V12: 1170235000 | W12: 944990000 | X12: 1048492000 | Y12: 1161364000 | Z12: 1023001000
A13: (Ara Toplam) | B13: 257051476000 | C13: 275790750346 | D13: 229845844000 | E13: 212417591000 | F13: 190897349000 | G13: 239344848455 | H13: 179786255000 | I13: 152319925000 | J13: 152185324000 | K13: 134518116000 | L13: 121635164000 | M13: 106012576000 | N13: 84645089000 | O13: 80656225000 | P13: 85462002000 | Q13: 80755626000 | R13: 67780864000 | S13: 65693526000 | T13: 40156967000 | U13: 33396936000 | V13: 27112480000 | W13: 28507242000 | X13: 31035758000 | Y13: 29162120000 | Z13: 26708242000
A14: Satış Amacıyla Elde Tutulan Duran Varlıklar | B14: 0 | C14: 0 | D14: 0 | E14: 0 | F14: 0 | G14: 0 | H14: 0 | I14: 0 | J14: 0 | K14: 0 | L14: 0 | M14: 0 | N14: 0 | O14: 0 | P14: 0 | Q14: 0 | R14: 0 | S14: 0 | T14: 0 | U14: 0 | V14: 0 | W14: 0 | X14: 0 | Y14: 0 | Z14: 0
... A72: TOPLAM KAYNAKLAR | B72: 576746036000 | C72: 614608667662 | D72: 523646428000 | E72: 492364562000 | F72: 454840822000 | G72: 556500482101 | H72: 405221132000 | I72: 363033297000 | J72: 349880224000 | K72: 310033249000 | L72: 277576670000 | M72: 247069595000 | N72: 184528793000 | O72: 174893623000 | P72: 175127517000 | Q72: 158784763000 | R72: 135204630000 | S72: 126442297000 | T72: 80164100000 | U72: 72120265000 | V72: 63329538000 | W72: 57993912000 | X72: 61502426000 | Y72: 55471961000 | Z72: 51381917000
A73: Gelir Tablosu
A74: Sürdürülen Faaliyetler | B74: 0 | C74: 0 | D74: 0 | E74: 0 | F74: 0 | G74: 0 | H74: 0 | I74: 0 | J74: 0 | K74: 0 | L74: 0 | M74: 0 | N74: 0 | O74: 0 | P74: 0 | Q74: 0 | R74: 0 | S74: 0 | T74: 0 | U74: 0 | V74: 0 | W74: 0 | X74: 0 | Y74: 0 | Z74: 0
A75: Satış Gelirleri | B75: 59684847000 | C75: 229884810210 | D75: 147915207000 | E75: 94957592000 | F75: 53544627000 | G75: 267098807580 | H75: 148946763000 | I75: 100218054000 | J75: 49747633000 | K75: 147899792000 | L75: 101010326000 | M75: 63619932000 | N75: 26273984000 | O75: 127782881000 | P75: 100535316000 | Q75: 63812753000 | R75: 29204128000 | S75: 68227404000 | T75: 43060307000 | U75: 24797566000 | V75: 10464203000 | W75: 32048029000 | X75: 21936023000 | Y75: 13783158000 | Z75: 6378927000
A76: Satışların Maliyeti (-) | B76: -54879228000 | C76: -209456210573 | D76: -136076956000 | E76: -87290004000 | F76: -49743369000 | G76: -240914315541 | H76: -131351920000 | I76: -86952034000 | J76: -42718340000 | K76: -132242934000 | L76: -91436527000 | M76: -58866951000 | N76: -25148401000 | O76: -102244085000 | P76: -75556602000 | Q76: -43859884000 | R76: -19755417000 | S76: -42710993000 | T76: -26789372000 | U76: -15760536000 | V76: -6810111000 | W76: -26123431000 | X76: -18444861000 | Y76: -11716960000 | Z76: -5501248000
A77: Ticari Faaliyetlerden Diğer Kar (Zarar) | B77: 0 | C77: 0 | D77: 0 | E77: 0 | F77: 0 | G77: 0 | H77: 0 | I77: 0 | J77: 0 | K77: 0 | L77: 0 | M77: 0 | N77: 0 | O77: 0 | P77: 0 | Q77: 0 | R77: 0 | S77: 0 | T77: 0 | U77: 0 | V77: 0 | W77: 0 | X77: 0 | Y77: 0 | Z77: 0
A78: Ticari Faaliyetlerden Brüt Kar (Zarar) | B78: 4805619000 | C78: 20428599637 | D78: 11838251000 | E78: 7667588000 | F78: 3801258000 | G78: 26184492040 | H78: 17594843000 | I78: 13266020000 | J78: 7029293000 | K78: 15656858000 | L78: 9573799000 | M78: 4752981000 | N78: 1125583000 | O78: 25538796000 | P78: 24978714000 | Q78: 19952869000 | R78: 9448711000 | S78: 25516411000 | T78: 16270935000 | U78: 9037030000 | V78: 3654092000 | W78: 5924598000 | X78: 3491162000 | Y78: 2066198000 | Z78: 877679000
A79: Faiz, Ücret, Prim, Komisyon ve Diğer Gelirler | B79: 0 | C79: 0 | D79: 0 | E79: 0 | F79: 0 | G79: 0 | H79: 0 | I79: 0 | J79: 0 | K79: 0 | L79: 0 | M79: 0 | N79: 0 | O79: 0 | P79: 0 | Q79: 0 | R79: 0 | S79: 0 | T79: 0 | U79: 0 | V79: 0 | W79: 0 | X79: 0 | Y79: 0 | Z79: 0
A80: Faiz, Ücret, Prim, Komisyon ve Diğer Giderler (-) | B80: 0 | C80: 0 | D80: 0 | E80: 0 | F80: 0 | G80: 0 | H80: 0 | I80: 0 | J80: 0 | K80: 0 | L80: 0 | M80: 0 | N80: 0 | O80: 0 | P80: 0 | Q80: 0 | R80: 0 | S80: 0 | T80: 0 | U80: 0 | V80: 0 | W80: 0 | X80: 0 | Y80: 0 | Z80: 0
A81: Finans Sektörü Faaliyetlerinden Diğer Kar (Zarar) | B81: 0 | C81: 0 | D81: 0 | E81: 0 | F81: 0 | G81: 0 | H81: 0 | I81: 0 | J81: 0 | K81: 0 | L81: 0 | M81: 0 | N81: 0 | O81: 0 | P81: 0 | Q81: 0 | R81: 0 | S81: 0 | T81: 0 | U81: 0 | V81: 0 | W81: 0 | X81: 0 | Y81: 0 | Z81: 0
A82: Finans Sektörü Faaliyetlerinden Brüt Kar (Zarar) | B82: 0 | C82: 0 | D82: 0 | E82: 0 | F82: 0 | G82: 0 | H82: 0 | I82: 0 | J82: 0 | K82: 0 | L82: 0 | M82: 0 | N82: 0 | O82: 0 | P82: 0 | Q82: 0 | R82: 0 | S82: 0 | T82: 0 | U82: 0 | V82: 0 | W82: 0 | X82: 0 | Y82: 0 | Z82: 0
A83: Diğer Gelir ve Giderler | B83: 0 | C83: 0 | D83: 0 | E83: 0 | F83: 0 | G83: 0 | H83: 0 | I83: 0 | J83: 0 | K83: 0 | L83: 0 | M83: 0 | N83: 0 | O83: 0 | P83: 0 | Q83: 0 | R83: 0 | S83: 0 | T83: 0 | U83: 0 | V83: 0 | W83: 0 | X83: 0 | Y83: 0 | Z83: 0
A84: BRÜT KAR (ZARAR) | B84: 4805619000 | C84: 20428599637 | D84: 11838251000 | E84: 7667588000 | F84: 3801258000 | G84: 26184492040 | H84: 17594843000 | I84: 13266020000 | J84: 7029293000 | K84: 15656858000 | L84: 9573799000 | M84: 4752981000 | N84: 1125583000 | O84: 25538796000 | P84: 24978714000 | Q84: 19952869000 | R84: 9448711000 | S84: 25516411000 | T84: 16270935000 | U84: 9037030000 | V84: 3654092000 | W84: 5924598000 | X84: 3491162000 | Y84: 2066198000 | Z84: 877679000
A85: Pazarlama, Satış ve Dağıtım Giderleri (-) | B85: -705628000 | C85: -2841131510 | D85: -1893830000 | E85: -1211057000 | F85: -559266000 | G85: -2692957830 | H85: -1466965000 | I85: -938249000 | J85: -431256000 | K85: -1177995000 | L85: -812365000 | M85: -532072000 | N85: -187274000 | O85: -741626000 | P85: -534189000 | Q85: -335927000 | R85: -152166000 | S85: -379587000 | T85: -247840000 | U85: -166165000 | V85: -73714000 | W85: -257809000 | X85: -191979000 | Y85: -126287000 | Z85: -57537000
... A116: Sürdürülen Faaliyetlerden Seyreltilmiş Hisse Başına Kazanç | B116: 0 | C116: 0 | D116: 0 | E116: 0 | F116: 0 | G116: 3 | H116: 2 | I116: 1 | J116: 1 | K116: 1 | L116: -1 | M116: -1 | N116: 0 | O116: 5 | P116: 4 | Q116: 0 | R116: 0 | S116: 0 | T116: 0 | U116: 0 | V116: 0 | W116: 0 | X116: 0 | Y116: 0 | Z116: 0
A117: Dipnot
A118: Amortisman Giderleri | B118: 3676129000 | C118: 12429722573 | D118: 7951219000 | E118: 4982030000 | F118: 2368275000 | G118: 11567261383 | H118: 6315906000 | I118: 4110744000 | J118: 1988437000 | K118: 5372718000 | L118: 3617629000 | M118: 2314170000 | N118: 1057771000 | O118: 3493831000 | P118: 2642081000 | Q118: 1668159000 | R118: 782075000 | S118: 2051931000 | T118: 1325825000 | U118: 890226000 | V118: 409835000 | W118: 1525473000 | X118: 1049722000 | Y118: 649938000 | Z118: 302964000
A119: Kıdem Tazminatı | B119: 159587000 | C119: 439967003 | D119: 343344000 | E119: 232778000 | F119: 131618000 | G119: 495695794 | H119: 305658000 | I119: 202959000 | J119: 120561000 | K119: 511408000 | L119: 454945000 | M119: 387751000 | N119: 86093000 | O119: 146603000 | P119: 101938000 | Q119: 56871000 | R119: 29062000 | S119: 80464000 | T119: 54830000 | U119: 35463000 | V119: 16963000 | W119: 55790000 | X119: 44854000 | Y119: 30988000 | Z119: 13453000
A120: Finansman Giderleri | B120: -3212593000 | C120: -14671112057 | D120: -10815587000 | E120: -7433987000 | F120: -4074286000 | G120: -17019898098 | H120: -9604823000 | I120: -5773352000 | J120: -3203616000 | K120: -9101977000 | L120: -5933340000 | M120: -4360375000 | N120: -1164858000 | O120: -3042783000 | P120: -1835741000 | Q120: -1220394000 | R120: -717232000 | S120: -1676598000 | T120: -325373000 | U120: -215370000 | V120: -105642000 | W120: -543079000 | X120: -370002000 | Y120: -266734000 | Z120: -130846000
A121: Yurtiçi Satışlar | B121: 48394620000 | C121: 161460104754 | D121: 107400847000 | E121: 67628161000 | F121: 36761452000 | G121: 205133131730 | H121: 113011359000 | I121: 77618410000 | J121: 40136578000 | K121: 124640941000 | L121: 85949094000 | M121: 54006534000 | N121: 22389402000 | O121: 102953785000 | P121: 80846370000 | Q121: 51890261000 | R121: 23390190000 | S121: 51422587000 | T121: 33372124000 | U121: 20234451000 | V121: 8981961000 | W121: 26045753000 | X121: 17573681000 | Y121: 10875927000 | Z121: 5448761000
A122: Yurtdışı Satışlar | B122: 9325184000 | C122: 49015984509 | D122: 31922880000 | E122: 22028149000 | F122: 15205230000 | G122: 53033911874 | H122: 27837788000 | I122: 17269236000 | J122: 6974068000 | K122: 15902785000 | L122: 9991111000 | M122: 5954704000 | N122: 2311836000 | O122: 18515681000 | P122: 15065496000 | Q122: 9008765000 | R122: 4594283000 | S122: 14038005000 | T122: 7969145000 | U122: 4052464000 | V122: 1199307000 | W122: 5190683000 | X122: 3800245000 | Y122: 2527870000 | Z122: 702608000
A123: Net Yabancı Para Pozisyonu | B123: -5100280000 | C123: -486394050 | D123: -536703000 | E123: 11968168000 | F123: 28471240000 | G123: 6612844066 | H123: 4376736000 | I123: 3374712000 | J123: 1227248000 | K123: 609319000 | L123: -154253000 | M123: 89911000 | N123: 7026138000 | O123: -4740136000 | P123: -8003651000 | Q123: -9664157000 | R123: -8110523000 | S123: 3418743000 | T123: 1974195000 | U123: -3636446000 | V123: -3264936000 | W123: -1106624000 | X123: 748787000 | Y123: 1931610000 | Z123: 9185328000
A124: Parasal net yabancı para varlık/(yükümlülük) pozisyonu | B124: -9671157000 | C124: -7888174453 | D124: -5610573000 | E124: 6384496000 | F124: 23842309000 | G124: 674835035 | H124: -2150604000 | I124: -4526779000 | J124: -5313740000 | K124: -659605000 | L124: -6556033000 | M124: -6208192000 | N124: 3554226000 | O124: -7556744000 | P124: -10668417000 | Q124: -11866319000 | R124: -9972845000 | S124: 1992663000 | T124: 917829000 | U124: -4946950000 | V124: -4167238000 | W124: -1770023000 | X124: -61052000 | Y124: 1184683000 | Z124: 8697022000
A125: Net YPP (Hedge Dahil) | B125: -5256331000 | C125: -1881357860 | D125: -4121422000 | E125: -1708378000 | F125: 7419576000 | G125: 3944656300 | H125: 2692243000 | I125: 1254617000 | J125: -655181000 | K125: 609319000 | L125: -1072038000 | M125: -1388775000 | N125: 6064401000 | O125: -5659030000 | P125: -9146407000 | Q125: -12686139000 | R125: -9367000000 | S125: 1630353000 | T125: -2800002000 | U125: -5300167000 | V125: -4080555000 | W125: -1303197000 | X125: -130979000 | Y125: 959591000 | Z125: -945050000
A126: Nakit Akım Tablosu
A127: İşletme Faaliyetlerinden Kaynaklanan Net Nakit | B127: 18061920000 | C127: 71587251092 | D127: 47211505000 | E127: 34035787000 | F127: 19077458000 | G127: 40913932763 | H127: 12741710000 | I127: 7814557000 | J127: 2562131000 | K127: 13068139000 | L127: 7156472000 | M127: 2811493000 | N127: 4007685000 | O127: 8940221000 | P127: 754598000 | Q127: 566197000 | R127: 3538617000 | S127: 5716945000 | T127: 6027960000 | U127: 4634825000 | V127: 2396006000 | W127: 7315515000 | X127: 5432084000 | Y127: 3149292000 | Z127: 2189025000
...

Sheet Historical
A1: EREGL - Historical Financials (TRY, real - inflation adjusted)
A2: Source: İş Yatırım, quarterly financials
B3: 2020/12 | C3: 2021/12 | D3: 2022/12 | E3: 2023/12 | F3: 2024/12 | G3: 2025/12
A4: Revenue | B4: =INDEX(isyatirim!$A$1:$Z$152,MATCH("Satış Gelirleri",isyatirim!$A$1:$A$152,0),MATCH(B$3,isyatirim!$A$1:$Z$1,0)) -> 32048029000 | C4: =INDEX(isyatirim!$A$1:$Z$152,MATCH("Satış Gelirleri",isyatirim!$A$1:$A$152,0),MATCH(C$3,isyatirim!$A$1:$Z$1,0)) -> 68227404000 | D4: =INDEX(isyatirim!$A$1:$Z$152,MATCH("Satış Gelirleri",isyatirim!$A$1:$A$152,0),MATCH(D$3,isyatirim!$A$1:$Z$1,0)) -> 127782881000 | E4: =INDEX(isyatirim!$A$1:$Z$152,MATCH("Satış Gelirleri",isyatirim!$A$1:$A$152,0),MATCH(E$3,isyatirim!$A$1:$Z$1,0)) -> 147899792000 | F4: =INDEX(isyatirim!$A$1:$Z$152,MATCH("Satış Gelirleri",isyatirim!$A$1:$A$152,0),MATCH(F$3,isyatirim!$A$1:$Z$1,0)) -> 267098807580 | G4: =INDEX(isyatirim!$A$1:$Z$152,MATCH("Satış Gelirleri",isyatirim!$A$1:$A$152,0),MATCH(G$3,isyatirim!$A$1:$Z$1,0)) -> 229884810210
A5: COGS | B5: =INDEX(isyatirim!$A$1:$Z$152,MATCH("Satışların Maliyeti (-)",isyatirim!$A$1:$A$152,0),MATCH(B$3,isyatirim!$A$1:$Z$1,0)) -> -26123431000 | C5: =INDEX(isyatirim!$A$1:$Z$152,MATCH("Satışların Maliyeti (-)",isyatirim!$A$1:$A$152,0),MATCH(C$3,isyatirim!$A$1:$Z$1,0)) -> -42710993000 | D5: =INDEX(isyatirim!$A$1:$Z$152,MATCH("Satışların Maliyeti (-)",isyatirim!$A$1:$A$152,0),MATCH(D$3,isyatirim!$A$1:$Z$1,0)) -> -102244085000 | E5: =INDEX(isyatirim!$A$1:$Z$152,MATCH("Satışların Maliyeti (-)",isyatirim!$A$1:$A$152,0),MATCH(E$3,isyatirim!$A$1:$Z$1,0)) -> -132242934000 | F5: =INDEX(isyatirim!$A$1:$Z$152,MATCH("Satışların Maliyeti (-)",isyatirim!$A$1:$A$152,0),MATCH(F$3,isyatirim!$A$1:$Z$1,0)) -> -240914315541 | G5: =INDEX(isyatirim!$A$1:$Z$152,MATCH("Satışların Maliyeti (-)",isyatirim!$A$1:$A$152,0),MATCH(G$3,isyatirim!$A$1:$Z$1,0)) -> -209456210573
A6: Gross Profit | B6: =B4+B5 -> 5924598000 | C6: =C4+C5 -> 25516411000 | D6: =D4+D5 -> 25538796000 | E6: =E4+E5 -> 15656858000 | F6: =F4+F5 -> 26184492039 | G6: =G4+G5 -> 20428599637
A7: Gross Margin % | B7: =B6/B4 -> 0.18486622 | C7: =C6/C4 -> 0.37399065 | D7: =D6/D4 -> 0.19986086 | E7: =E6/E4 -> 0.10586126 | F7: =F6/F4 -> 0.09803298 | G7: =G6/G4 -> 0.088864504
A8: Operating Expenses | B8: =INDEX(isyatirim!$A$1:$Z$152,MATCH("Pazarlama, Satış ve Dağıtım Giderleri (-)",isyatirim!$A$1:$A$152,0),MATCH(B$3,isyatirim!$A$1:$Z$1,0))+INDEX(isyatirim!$A$1:$Z$152,MATCH("Genel Yönetim Giderleri (-)",isyatirim!$A$1:$A$152,0),MATCH(B$3,isyatirim!$A$1:$Z$1,0))+INDEX(isyatirim!$A$1:$Z$152,MATCH("Araştırma ve Geliştirme Giderleri (-)",isyatirim!$A$1:$A$152,0),MATCH(B$3,isyatirim!$A$1:$Z$1,0)) -> -784806000 | C8: =INDEX(isyatirim!$A$1:$Z$152,MATCH("Pazarlama, Satış ve Dağıtım Giderleri (-)",isyatirim!$A$1:$A$152,0),MATCH(C$3,isyatirim!$A$1:$Z$1,0))+INDEX(isyatirim!$A$1:$Z$152,MATCH("Genel Yönetim Giderleri (-)",isyatirim!$A$1:$A$152,0),MATCH(C$3,isyatirim!$A$1:$Z$1,0))+INDEX(isyatirim!$A$1:$Z$152,MATCH("Araştırma ve Geliştirme Giderleri (-)",isyatirim!$A$1:$A$152,0),MATCH(C$3,isyatirim!$A$1:$Z$1,0)) -> -1100542000 | D8: =INDEX(isyatirim!$A$1:$Z$152,MATCH("Pazarlama, Satış ve Dağıtım Giderleri (-)",isyatirim!$A$1:$A$152,0),MATCH(D$3,isyatirim!$A$1:$Z$1,0))+INDEX(isyatirim!$A$1:$Z$152,MATCH("Genel Yönetim Giderleri (-)",isyatirim!$A$1:$A$152,0),MATCH(D$3,isyatirim!$A$1:$Z$1,0))+INDEX(isyatirim!$A$1:$Z$152,MATCH("Araştırma ve Geliştirme Giderleri (-)",isyatirim!$A$1:$A$152,0),MATCH(D$3,isyatirim!$A$1:$Z$1,0)) -> -2378120000 | E8: =INDEX(isyatirim!$A$1:$Z$152,MATCH("Pazarlama, Satış ve Dağıtım Giderleri (-)",isyatirim!$A$1:$A$152,0),MATCH(E$3,isyatirim!$A$1:$Z$1,0))+INDEX(isyatirim!$A$1:$Z$152,MATCH("Genel Yönetim Giderleri (-)",isyatirim!$A$1:$A$152,0),MATCH(E$3,isyatirim!$A$1:$Z$1,0))+INDEX(isyatirim!$A$1:$Z$152,MATCH("Araştırma ve Geliştirme Giderleri (-)",isyatirim!$A$1:$A$152,0),MATCH(E$3,isyatirim!$A$1:$Z$1,0)) -> -4041013000 | F8: =INDEX(isyatirim!$A$1:$Z$152,MATCH("Pazarlama, Satış ve Dağıtım Giderleri (-)",isyatirim!$A$1:$A$152,0),MATCH(F$3,isyatirim!$A$1:$Z$1,0))+INDEX(isyatirim!$A$1:$Z$152,MATCH("Genel Yönetim Giderleri (-)",isyatirim!$A$1:$A$152,0),MATCH(F$3,isyatirim!$A$1:$Z$1,0))+INDEX(isyatirim!$A$1:$Z$152,MATCH("Araştırma ve Geliştirme Giderleri (-)",isyatirim!$A$1:$A$152,0),MATCH(F$3,isyatirim!$A$1:$Z$1,0)) -> -10143523271 | G8: =INDEX(isyatirim!$A$1:$Z$152,MATCH("Pazarlama, Satış ve Dağıtım Giderleri (-)",isyatirim!$A$1:$A$152,0),MATCH(G$3,isyatirim!$A$1:$Z$1,0))+INDEX(isyatirim!$A$1:$Z$152,MATCH("Genel Yönetim Giderleri (-)",isyatirim!$A$1:$A$152,0),MATCH(G$3,isyatirim!$A$1:$Z$1,0))+INDEX(isyatirim!$A$1:$Z$152,MATCH("Araştırma ve Geliştirme Giderleri (-)",isyatirim!$A$1:$A$152,0),MATCH(G$3,isyatirim!$A$1:$Z$1,0)) -> -10353705857
A9: EBIT | B9: =B6+B8 -> 5139792000 | C9: =C6+C8 -> 24415869000 | D9: =D6+D8 -> 23160676000 | E9: =E6+E8 -> 11615845000 | F9: =F6+F8 -> 16040968768 | G9: =G6+G8 -> 10074893780
A10: EBIT Margin % | B10: =B9/B4 -> 0.16037779 | C10: =C9/C4 -> 0.35786015 | D10: =D9/D4 -> 0.18125023 | E10: =E9/E4 -> 0.078538616 | F10: =F9/F4 -> 0.06005631 | G10: =G9/G4 -> 0.043825835
A11: D&A | B11: =INDEX(isyatirim!$A$1:$Z$152,MATCH("Amortisman & İtfa Payları",isyatirim!$A$1:$A$152,0),MATCH(B$3,isyatirim!$A$1:$Z$1,0)) -> 1525473000 | C11: =INDEX(isyatirim!$A$1:$Z$152,MATCH("Amortisman & İtfa Payları",isyatirim!$A$1:$A$152,0),MATCH(C$3,isyatirim!$A$1:$Z$1,0)) -> 2051931000 | D11: =INDEX(isyatirim!$A$1:$Z$152,MATCH("Amortisman & İtfa Payları",isyatirim!$A$1:$A$152,0),MATCH(D$3,isyatirim!$A$1:$Z$1,0)) -> 3493831000 | E11: =INDEX(isyatirim!$A$1:$Z$152,MATCH("Amortisman & İtfa Payları",isyatirim!$A$1:$A$152,0),MATCH(E$3,isyatirim!$A$1:$Z$1,0)) -> 5372718000 | F11: =INDEX(isyatirim!$A$1:$Z$152,MATCH("Amortisman & İtfa Payları",isyatirim!$A$1:$A$152,0),MATCH(F$3,isyatirim!$A$1:$Z$1,0)) -> 11567261383 | G11: =INDEX(isyatirim!$A$1:$Z$152,MATCH("Amortisman & İtfa Payları",isyatirim!$A$1:$A$152,0),MATCH(G$3,isyatirim!$A$1:$Z$1,0)) -> 12429722573
A12: EBITDA | B12: =B9+B11 -> 6665265000 | C12: =C9+C11 -> 26467800000 | D12: =D9+D11 -> 26654507000 | E12: =E9+E11 -> 16988563000 | F12: =F9+F11 -> 27608230151 | G12: =G9+G11 -> 22504616353
A13: EBITDA Margin % | B13: =B12/B4 -> 0.20797738 | C13: =C12/C4 -> 0.38793503 | D13: =D12/D4 -> 0.20859216 | E13: =E12/E4 -> 0.11486536 | F13: =F12/F4 -> 0.10336336 | G13: =G12/G4 -> 0.097895186
A14: CAPEX | B14: =INDEX(isyatirim!$A$1:$Z$152,MATCH("Sabit Sermaye Yatırımları",isyatirim!$A$1:$A$152,0),MATCH(B$3,isyatirim!$A$1:$Z$1,0)) -> -1983720000 | C14: =INDEX(isyatirim!$A$1:$Z$152,MATCH("Sabit Sermaye Yatırımları",isyatirim!$A$1:$A$152,0),MATCH(C$3,isyatirim!$A$1:$Z$1,0)) -> -3839773000 | D14: =INDEX(isyatirim!$A$1:$Z$152,MATCH("Sabit Sermaye Yatırımları",isyatirim!$A$1:$A$152,0),MATCH(D$3,isyatirim!$A$1:$Z$1,0)) -> -11345081000 | E14: =INDEX(isyatirim!$A$1:$Z$152,MATCH("Sabit Sermaye Yatırımları",isyatirim!$A$1:$A$152,0),MATCH(E$3,isyatirim!$A$1:$Z$1,0)) -> -22765078000 | F14: =INDEX(isyatirim!$A$1:$Z$152,MATCH("Sabit Sermaye Yatırımları",isyatirim!$A$1:$A$152,0),MATCH(F$3,isyatirim!$A$1:$Z$1,0)) -> -45959596431 | G14: =INDEX(isyatirim!$A$1:$Z$152,MATCH("Sabit Sermaye Yatırımları",isyatirim!$A$1:$A$152,0),MATCH(G$3,isyatirim!$A$1:$Z$1,0)) -> -16887458599
A15: CAPEX / Revenue % | B15: =-B14/B4 -> 0.061898346 | C15: =-C14/C4 -> 0.056279043 | D15: =-D14/D4 -> 0.088784045 | E15: =-E14/E4 -> 0.15392231 | F15: =-F14/F4 -> 0.17206964 | G15: =-G14/G4 -> 0.073460524
A16: D&A / Revenue % | B16: =B11/B4 -> 0.047599589 | C16: =C11/C4 -> 0.03007488 | D16: =D11/D4 -> 0.027341933 | E16: =E11/E4 -> 0.036326745 | F16: =F11/F4 -> 0.04330705 | G16: =G11/G4 -> 0.054069351
A17: Tax Expense | B17: =INDEX(isyatirim!$A$1:$Z$152,MATCH("Sürdürülen Faaliyetler Vergi Geliri (Gideri)",isyatirim!$A$1:$A$152,0),MATCH(B$3,isyatirim!$A$1:$Z$1,0)) -> -2147735000 | C17: =INDEX(isyatirim!$A$1:$Z$152,MATCH("Sürdürülen Faaliyetler Vergi Geliri (Gideri)",isyatirim!$A$1:$A$152,0),MATCH(C$3,isyatirim!$A$1:$Z$1,0)) -> -7838155000 | D17: =INDEX(isyatirim!$A$1:$Z$152,MATCH("Sürdürülen Faaliyetler Vergi Geliri (Gideri)",isyatirim!$A$1:$A$152,0),MATCH(D$3,isyatirim!$A$1:$Z$1,0)) -> -3459400000 | E17: =INDEX(isyatirim!$A$1:$Z$152,MATCH("Sürdürülen Faaliyetler Vergi Geliri (Gideri)",isyatirim!$A$1:$A$152,0),MATCH(E$3,isyatirim!$A$1:$Z$1,0)) -> -4508065000 | F17: =INDEX(isyatirim!$A$1:$Z$152,MATCH("Sürdürülen Faaliyetler Vergi Geliri (Gideri)",isyatirim!$A$1:$A$152,0),MATCH(F$3,isyatirim!$A$1:$Z$1,0)) -> 877927572 | G17: =INDEX(isyatirim!$A$1:$Z$152,MATCH("Sürdürülen Faaliyetler Vergi Geliri (Gideri)",isyatirim!$A$1:$A$152,0),MATCH(G$3,isyatirim!$A$1:$Z$1,0)) -> -3285920473
A18: Pre-Tax Income | B18: =INDEX(isyatirim!$A$1:$Z$152,MATCH("SÜRDÜRÜLEN FAALİYETLER VERGİ ÖNCESİ KARI (ZARARI)",isyatirim!$A$1:$A$152,0),MATCH(B$3,isyatirim!$A$1:$Z$1,0)) -> 5657525000 | C18: =INDEX(isyatirim!$A$1:$Z$152,MATCH("SÜRDÜRÜLEN FAALİYETLER VERGİ ÖNCESİ KARI (ZARARI)",isyatirim!$A$1:$A$152,0),MATCH(C$3,isyatirim!$A$1:$Z$1,0)) -> 23916713000 | D18: =INDEX(isyatirim!$A$1:$Z$152,MATCH("SÜRDÜRÜLEN FAALİYETLER VERGİ ÖNCESİ KARI (ZARARI)",isyatirim!$A$1:$A$152,0),MATCH(D$3,isyatirim!$A$1:$Z$1,0)) -> 22112454000 | E18: =INDEX(isyatirim!$A$1:$Z$152,MATCH("SÜRDÜRÜLEN FAALİYETLER VERGİ ÖNCESİ KARI (ZARARI)",isyatirim!$A$1:$A$152,0),MATCH(E$3,isyatirim!$A$1:$Z$1,0)) -> 8837129000 | F18: =INDEX(isyatirim!$A$1:$Z$152,MATCH("SÜRDÜRÜLEN FAALİYETLER VERGİ ÖNCESİ KARI (ZARARI)",isyatirim!$A$1:$A$152,0),MATCH(F$3,isyatirim!$A$1:$Z$1,0)) -> 17699680862 | G18: =INDEX(isyatirim!$A$1:$Z$152,MATCH("SÜRDÜRÜLEN FAALİYETLER VERGİ ÖNCESİ KARI (ZARARI)",isyatirim!$A$1:$A$152,0),MATCH(G$3,isyatirim!$A$1:$Z$1,0)) -> 4049978881
A19: Effective Tax Rate % | B19: =-B17/B18 -> 0.37962448 | C19: =-C17/C18 -> 0.3277271 | D19: =-D17/D18 -> 0.15644577 | E19: =-E17/E18 -> 0.51012778 | F19: =-F17/F18 -> -0.049601322 | G19: =-G17/G18 -> 0.81134262
A21: Short-term Debt | B21: =INDEX(isyatirim!$A$1:$Z$152,34,MATCH(B$3,isyatirim!$A$1:$Z$1,0)) -> 3785528000 | C21: =INDEX(isyatirim!$A$1:$Z$152,34,MATCH(C$3,isyatirim!$A$1:$Z$1,0)) -> 9715673000 | D21: =INDEX(isyatirim!$A$1:$Z$152,34,MATCH(D$3,isyatirim!$A$1:$Z$1,0)) -> 21172290000 | E21: =INDEX(isyatirim!$A$1:$Z$152,34,MATCH(E$3,isyatirim!$A$1:$Z$1,0)) -> 56761083000 | F21: =INDEX(isyatirim!$A$1:$Z$152,34,MATCH(F$3,isyatirim!$A$1:$Z$1,0)) -> 48051966591 | G21: =INDEX(isyatirim!$A$1:$Z$152,34,MATCH(G$3,isyatirim!$A$1:$Z$1,0)) -> 44034852326
A22: Long-term Debt | B22: =INDEX(isyatirim!$A$1:$Z$152,48,MATCH(B$3,isyatirim!$A$1:$Z$1,0)) -> 2812743000 | C22: =INDEX(isyatirim!$A$1:$Z$152,48,MATCH(C$3,isyatirim!$A$1:$Z$1,0)) -> 6960671000 | D22: =INDEX(isyatirim!$A$1:$Z$152,48,MATCH(D$3,isyatirim!$A$1:$Z$1,0)) -> 8408449000 | E22: =INDEX(isyatirim!$A$1:$Z$152,48,MATCH(E$3,isyatirim!$A$1:$Z$1,0)) -> 10979619000 | F22: =INDEX(isyatirim!$A$1:$Z$152,48,MATCH(F$3,isyatirim!$A$1:$Z$1,0)) -> 110704977693 | G22: =INDEX(isyatirim!$A$1:$Z$152,48,MATCH(G$3,isyatirim!$A$1:$Z$1,0)) -> 130203735212
A23: Cash & Equivalents | B23: =INDEX(isyatirim!$A$1:$Z$152,MATCH("Nakit ve Nakit Benzerleri",isyatirim!$A$1:$A$152,0),MATCH(B$3,isyatirim!$A$1:$Z$1,0)) -> 13542177000 | C23: =INDEX(isyatirim!$A$1:$Z$152,MATCH("Nakit ve Nakit Benzerleri",isyatirim!$A$1:$A$152,0),MATCH(C$3,isyatirim!$A$1:$Z$1,0)) -> 23189668000 | D23: =INDEX(isyatirim!$A$1:$Z$152,MATCH("Nakit ve Nakit Benzerleri",isyatirim!$A$1:$A$152,0),MATCH(D$3,isyatirim!$A$1:$Z$1,0)) -> 15186458000 | E23: =INDEX(isyatirim!$A$1:$Z$152,MATCH("Nakit ve Nakit Benzerleri",isyatirim!$A$1:$A$152,0),MATCH(E$3,isyatirim!$A$1:$Z$1,0)) -> 24072967000 | F23: =INDEX(isyatirim!$A$1:$Z$152,MATCH("Nakit ve Nakit Benzerleri",isyatirim!$A$1:$A$152,0),MATCH(F$3,isyatirim!$A$1:$Z$1,0)) -> 72331091723 | G23: =INDEX(isyatirim!$A$1:$Z$152,MATCH("Nakit ve Nakit Benzerleri",isyatirim!$A$1:$A$152,0),MATCH(G$3,isyatirim!$A$1:$Z$1,0)) -> 127070780476
A24: Net Debt | B24: =B21+B22-B23 -> -6943906000 | C24: =C21+C22-C23 -> -6513324000 | D24: =D21+D22-D23 -> 14394281000 | E24: =E21+E22-E23 -> 43667735000 | F24: =F21+F22-F23 -> 86425852561 | G24: =G21+G22-G23 -> 47167807062
A27: YoY Growth Rates (Real)
A28: Revenue Growth % | C28: =C4/B4-1 -> 1.1289111 | D28: =D4/C4-1 -> 0.87289672 | E28: =E4/D4-1 -> 0.15743041 | F28: =F4/E4-1 -> 0.80594444 | G28: =G4/F4-1 -> -0.13932671
A29: EBIT Growth % | C29: =C9/B9-1 -> 3.7503613 | D29: =D9/C9-1 -> -0.051408901 | E29: =E9/D9-1 -> -0.49846693 | F29: =F9/E9-1 -> 0.38095582 | G29: =G9/F9-1 -> -0.37192735
A30: EBITDA Growth % | C30: =C12/B12-1 -> 2.9710049 | D30: =D12/C12-1 -> 0.0070541186 | E30: =E12/D12-1 -> -0.36263826 | F30: =F12/E12-1 -> 0.62510685 | G30: =G12/F12-1 -> -0.18485842
A31: CAPEX Growth % | C31: =C14/B14-1 -> 0.93564263 | D31: =D14/C14-1 -> 1.9546228 | E31: =E14/D14-1 -> 1.0066034 | F31: =F14/E14-1 -> 1.018864 | G31: =G14/F14-1 -> -0.6325586
A33: Multi-Year Averages
A34: Avg Gross Margin (6Y) | B34: =AVERAGE(B7:G7) -> 0.17524608
A35: Avg EBIT Margin (6Y) | B35: =AVERAGE(B10:G10) -> 0.14698482
A36: Avg EBITDA Margin (6Y) | B36: =AVERAGE(B13:G13) -> 0.18677141
A37: Avg CAPEX/Revenue (6Y) | B37: =AVERAGE(B15:G15) -> 0.10106899
A38: Avg D&A / Revenue (6Y) | B38: =AVERAGE(B16:G16) -> 0.039786591
A40: CAGR Analysis
A41: Revenue CAGR (5Y, 2020→2025) | B41: =(G4/B4)^(1/5)-1 -> 0.48300218
A42: EBITDA CAGR (5Y, 2020→2025) | B42: =(G12/B12)^(1/5)-1 -> 0.27553047

Sheet Projections_TL
A1: EREGL - 5Y Forward Projections (Real TRY)
A2: Base Case
B3: 2026E | C3: 2027E | D3: 2028E | E3: 2029E | F3: 2030E | G3: 2025A
A5: Revenue Growth % | B5: 0.08 | C5: 0.05 | D5: 0.04 | E5: 0.03 | F5: 0.03
A6: Revenue | B6: =G6*(1+B5) -> 2.482756e+11 | C6: =B6*(1+C5) -> 2.6068937e+11 | D6: =C6*(1+D5) -> 2.7111695e+11 | E6: =D6*(1+E5) -> 2.7925046e+11 | F6: =E6*(1+F5) -> 2.8762797e+11 | G6: =Historical!G4 -> 229884810210
A8: Gross Margin % | B8: 0.1 | C8: 0.12 | D8: 0.13 | E8: 0.14 | F8: 0.14
A9: Gross Profit | B9: =B8*B6 -> 2.482756e+10 | C9: =C8*C6 -> 3.1282725e+10 | D9: =D8*D6 -> 3.5245203e+10 | E9: =E8*E6 -> 3.9095064e+10 | F9: =F8*F6 -> 4.0267916e+10 | G9: =Historical!G6 -> 20428599637
A11: OpEx / Revenue % | B11: 0.04 | C11: 0.04 | D11: 0.04 | E11: 0.04 | F11: 0.04
A12: OpEX | B12: =-B6*B11 -> -9.9310238e+09 | C12: =-C6*C11 -> -1.0427575e+10 | D12: =-D6*D11 -> -1.0844678e+10 | E12: =-E6*E11 -> -1.1170018e+10 | F12: =-F6*F11 -> -1.1505119e+10 | G12: =Historical!G8 -> -10353705857
A14: EBIT | B14: =B9+B12 -> 1.4896536e+10 | C14: =C9+C12 -> 2.085515e+10 | D14: =D9+D12 -> 2.4400525e+10 | E14: =E9+E12 -> 2.7925046e+10 | F14: =F9+F12 -> 2.8762797e+10 | G14: =Historical!G9 -> 10074893780
A15: EBIT Margin % | B15: =B14/B6 -> 0.06 | C15: =C14/C6 -> 0.08 | D15: =D14/D6 -> 0.09 | E15: =E14/E6 -> 0.1 | F15: =F14/F6 -> 0.1
A17: D&A / Revenue % | B17: 0.055 | C17: 0.06 | D17: 0.065 | E17: 0.065 | F17: 0.065
A18: D&A | B18: =B6*B17 -> 1.3655158e+10 | C18: =C6*C17 -> 1.5641362e+10 | D18: =D6*D17 -> 1.7622602e+10 | E18: =E6*E17 -> 1.815128e+10 | F18: =F6*F17 -> 1.8695818e+10 | G18: =Historical!G11 -> 12429722573
A20: EBITDA | B20: =B14+B18 -> 2.8551693e+10 | C20: =C14+C18 -> 3.6496512e+10 | D20: =D14+D18 -> 4.2023127e+10 | E20: =E14+E18 -> 4.6076326e+10 | F20: =F14+F18 -> 4.7458615e+10 | G20: =Historical!G12 -> 22504616353
A21: EBITDA Margin % | B21: =B20/B6 -> 0.115 | C21: =C20/C6 -> 0.14 | D21: =D20/D6 -> 0.155 | E21: =E20/E6 -> 0.165 | F21: =F20/F6 -> 0.165
A23: Tax Rate % | B23: 0.25 | C23: 0.25 | D23: 0.25 | E23: 0.25 | F23: 0.25
A24: Tax Espense | B24: =-B14*B23 -> -3.7241339e+09 | C24: =-C14*C23 -> -5.2137875e+09 | D24: =-D14*D23 -> -6.1001314e+09 | E24: =-E14*E23 -> -6.9812615e+09 | F24: =-F14*F23 -> -7.1906993e+09
A25: EBIT x (1-tax) | B25: =B14+B24 -> 1.1172402e+10 | C25: =C14+C24 -> 1.5641362e+10 | D25: =D14+D24 -> 1.8300394e+10 | E25: =E14+E24 -> 2.0943784e+10 | F25: =F14+F24 -> 2.1572098e+10
A27: D&A (add) | B27: =B18 -> 1.3655158e+10 | C27: =C18 -> 1.5641362e+10 | D27: =D18 -> 1.7622602e+10 | E27: =E18 -> 1.815128e+10 | F27: =F18 -> 1.8695818e+10 | G27: =Historical!G11 -> 12429722573
A28: CAPEX / Revenue % | B28: 0.07 | C28: 0.06 | D28: 0.055 | E28: 0.05 | F28: 0.05
A29: CAPEX | B29: =-B6*B28 -> -1.7379292e+10 | C29: =-C6*C28 -> -1.5641362e+10 | D29: =-D6*D28 -> -1.4911432e+10 | E29: =-E6*E28 -> -1.3962523e+10 | F29: =-F6*F28 -> -1.4381399e+10 | G29: =Historical!G14 -> -16887458599
A30: ΔNWC / Revenue % | B30: 0.15 | C30: 0.15 | D30: 0.15 | E30: 0.15 | F30: 0.15
A31: ΔNWC | B31: =-(B6-G6)*B30 -> -2.7586177e+09 | C31: =-(C6-B6)*C30 -> -1.862067e+09 | D31: =-(D6-C6)*D30 -> -1.5641362e+09 | E31: =-(E6-D6)*E30 -> -1.2200263e+09 | F31: =-(F6-E6)*F30 -> -1.2566271e+09
A33: FCFF | B33: =B25+B27+B29+B31 -> 4.6896501e+09 | C33: =C25+C27+C29+C31 -> 1.3779296e+10 | D33: =D25+D27+D29+D31 -> 1.9447427e+10 | E33: =E25+E27+E29+E31 -> 2.3912515e+10 | F33: =F25+F27+F29+F31 -> 2.462989e+10
A35: Terminal Value Calculation
A37: Terminal Year FCFF (2030E) | B37: =F33 -> 2.462989e+10
A38: Terminal Growth Rate (g) | B38: 0.025
A39: WACC | B39: =WACC!B23 -> 0.14821392
A40: TV — Gordon Growth | B40: =B37*(1+B38)/(B39-B38) -> 2.0489274e+11
A42: Terminal Year EBITDA (2030E) | B42: =F20 -> 4.7458615e+10
A43: Exit Multiple (EV/EBITDA) | B43: 10
A44: TV — Exit Multiple | B44: =B42*B43 -> 4.7458615e+11
A45: TV (Average) | B45: =AVERAGE(B40,B44) -> 3.3973945e+11

Sheet WACC
A1: EREGL - WACC Calculation
A2: Real TRY
A4: Cost of Equity (CAPM)
A5: Risk-free rate (Rf, real) | B5: 0.055
A6: Beta | B6: 1
A7: Equity Risk Premium (ERP) | B7: 0.0423
A8: Country Risk Premium (CRP) | B8: 0.0664
A9: Cost of Equity (Re) | B9: =B5+B6*B7+B8 -> 0.1637
A11: Cost of Debt
A12: Pre-tax cost of debt (Rd) | B12: 0.09
A13: Tax rate (t) | B13: 0.25
A14: After-tax cost of debt | B14: =B12*(1-B13) -> 0.0675
A16: Capital Structure
A17: Market Cap (Equity, E) | B17: =DCF!B20*DCF!B18 -> 2.4584e+11
A18: Net Debt (D) | B18: =Historical!G24 -> 47167807062
A19: Total Capital (V) | B19: =B17+B18 -> 293007807062
A20: E/V | B20: =B17/B19 -> 0.83902201
A21: D/V | B21: =B18/B19 -> 0.16097799
A23: WACC (real TRY) | B23: =B20*B9+B21*B14 -> 0.14821392

Sheet DCF
A1: EREGL - DCF Valuation
A2: Real TRY
A4: Period | B4: 1 | C4: 2 | D4: 3 | E4: 4 | F4: 5
A5: Year | B5: 2026E | C5: 2027E | D5: 2028E | E5: 2029E | F5: 2030E
A6: FCFF | B6: =Projections_TL!B33 -> 4.6896501e+09 | C6: =Projections_TL!C33 -> 1.3779296e+10 | D6: =Projections_TL!D33 -> 1.9447427e+10 | E6: =Projections_TL!E33 -> 2.3912515e+10 | F6: =Projections_TL!F33 -> 2.462989e+10
A7: Discount Factor | B7: =1/(1+WACC!$B$23)^B4 -> 0.87091785 | C7: =1/(1+WACC!$B$23)^C4 -> 0.75849791 | D7: =1/(1+WACC!$B$23)^D4 -> 0.66058937 | E7: =1/(1+WACC!$B$23)^E4 -> 0.57531907 | F7: =1/(1+WACC!$B$23)^F4 -> 0.50105565
A8: PV of FCFF | B8: =B6*B7 -> 4.0843e+09 | C8: =C6*C7 -> 1.0451567e+10 | D8: =D6*D7 -> 1.2846764e+10 | E8: =E6*E7 -> 1.3757326e+10 | F8: =F6*F7 -> 1.2340946e+10
A11: Terminal Value (2030) | B11: =Projections_TL!B45 -> 3.3973945e+11
A12: Discount Factor (Year 5) | B12: =F7 -> 0.50105565
A13: PV of Terminal Value | B13: =B11*B12 -> 1.7022837e+11
A15: Enterprise Value (EV) | B15: =SUM(B8:F8)+B13 -> 2.2370927e+11
A16: (-) Net Debt | B16: =Historical!G24 -> 47167807062
A17: Equity Value | B17: =B15-B16 -> 1.7654147e+11
A18: Shares Outstanding | B18: 7000000000
A19: Implied Share Price (TRY) | B19: =B17/B18 -> 25.22021
A20: Current Share Price (TRY) | B20: 35.12
A21: Upside / (Downside) % | B21: =B19/B20-1 -> -0.28188469

Sheet Sensitivity
A1: EREGL - DCF Sensitivity Analysis
A2: Implied Share Price (TRY)
A5: WACC \ g | B5: 0.015 | C5: 0.02 | D5: 0.025 | E5: 0.03 | F5: 0.035
A6: 0.13 | B6: =(Projections_TL!$B$33/(1+$A6)^1+Projections_TL!$C$33/(1+$A6)^2+Projections_TL!$D$33/(1+$A6)^3+Projections_TL!$E$33/(1+$A6)^4+Projections_TL!$F$33/(1+$A6)^5+((Projections_TL!$F$33*(1+B$5)/($A6-B$5)+Projections_TL!$F$20*Projections_TL!$B$43)/2)/(1+$A6)^5-Historical!$G$24)/DCF!$B$18 -> 28.153278 | C6: =(Projections_TL!$B$33/(1+$A6)^1+Projections_TL!$C$33/(1+$A6)^2+Projections_TL!$D$33/(1+$A6)^3+Projections_TL!$E$33/(1+$A6)^4+Projections_TL!$F$33/(1+$A6)^5+((Projections_TL!$F$33*(1+C$5)/($A6-C$5)+Projections_TL!$F$20*Projections_TL!$B$43)/2)/(1+$A6)^5-Historical!$G$24)/DCF!$B$18 -> 28.57976 | D6: =(Projections_TL!$B$33/(1+$A6)^1+Projections_TL!$C$33/(1+$A6)^2+Projections_TL!$D$33/(1+$A6)^3+Projections_TL!$E$33/(1+$A6)^4+Projections_TL!$F$33/(1+$A6)^5+((Projections_TL!$F$33*(1+D$5)/($A6-D$5)+Projections_TL!$F$20*Projections_TL!$B$43)/2)/(1+$A6)^5-Historical!$G$24)/DCF!$B$18 -> 29.046859 | E6: =(Projections_TL!$B$33/(1+$A6)^1+Projections_TL!$C$33/(1+$A6)^2+Projections_TL!$D$33/(1+$A6)^3+Projections_TL!$E$33/(1+$A6)^4+Projections_TL!$F$33/(1+$A6)^5+((Projections_TL!$F$33*(1+E$5)/($A6-E$5)+Projections_TL!$F$20*Projections_TL!$B$43)/2)/(1+$A6)^5-Historical!$G$24)/DCF!$B$18 -> 29.560667 | F6: =(Projections_TL!$B$33/(1+$A6)^1+Projections_TL!$C$33/(1+$A6)^2+Projections_TL!$D$33/(1+$A6)^3+Projections_TL!$E$33/(1+$A6)^4+Projections_TL!$F$33/(1+$A6)^5+((Projections_TL!$F$33*(1+F$5)/($A6-F$5)+Projections_TL!$F$20*Projections_TL!$B$43)/2)/(1+$A6)^5-Historical!$G$24)/DCF!$B$18 -> 30.128561
A7: 0.14 | B7: =(Projections_TL!$B$33/(1+$A7)^1+Projections_TL!$C$33/(1+$A7)^2+Projections_TL!$D$33/(1+$A7)^3+Projections_TL!$E$33/(1+$A7)^4+Projections_TL!$F$33/(1+$A7)^5+((Projections_TL!$F$33*(1+B$5)/($A7-B$5)+Projections_TL!$F$20*Projections_TL!$B$43)/2)/(1+$A7)^5-Historical!$G$24)/DCF!$B$18 -> 26.114758 | C7: =(Projections_TL!$B$33/(1+$A7)^1+Projections_TL!$C$33/(1+$A7)^2+Projections_TL!$D$33/(1+$A7)^3+Projections_TL!$E$33/(1+$A7)^4+Projections_TL!$F$33/(1+$A7)^5+((Projections_TL!$F$33*(1+C$5)/($A7-C$5)+Projections_TL!$F$20*Projections_TL!$B$43)/2)/(1+$A7)^5-Historical!$G$24)/DCF!$B$18 -> 26.461969 | D7: =(Projections_TL!$B$33/(1+$A7)^1+Projections_TL!$C$33/(1+$A7)^2+Projections_TL!$D$33/(1+$A7)^3+Projections_TL!$E$33/(1+$A7)^4+Projections_TL!$F$33/(1+$A7)^5+((Projections_TL!$F$33*(1+D$5)/($A7-D$5)+Projections_TL!$F$20*Projections_TL!$B$43)/2)/(1+$A7)^5-Historical!$G$24)/DCF!$B$18 -> 26.839373 | E7: =(Projections_TL!$B$33/(1+$A7)^1+Projections_TL!$C$33/(1+$A7)^2+Projections_TL!$D$33/(1+$A7)^3+Projections_TL!$E$33/(1+$A7)^4+Projections_TL!$F$33/(1+$A7)^5+((Projections_TL!$F$33*(1+E$5)/($A7-E$5)+Projections_TL!$F$20*Projections_TL!$B$43)/2)/(1+$A7)^5-Historical!$G$24)/DCF!$B$18 -> 27.251085 | F7: =(Projections_TL!$B$33/(1+$A7)^1+Projections_TL!$C$33/(1+$A7)^2+Projections_TL!$D$33/(1+$A7)^3+Projections_TL!$E$33/(1+$A7)^4+Projections_TL!$F$33/(1+$A7)^5+((Projections_TL!$F$33*(1+F$5)/($A7-F$5)+Projections_TL!$F$20*Projections_TL!$B$43)/2)/(1+$A7)^5-Historical!$G$24)/DCF!$B$18 -> 27.702009
A8: 0.1483 | B8: =(Projections_TL!$B$33/(1+$A8)^1+Projections_TL!$C$33/(1+$A8)^2+Projections_TL!$D$33/(1+$A8)^3+Projections_TL!$E$33/(1+$A8)^4+Projections_TL!$F$33/(1+$A8)^5+((Projections_TL!$F$33*(1+B$5)/($A8-B$5)+Projections_TL!$F$20*Projections_TL!$B$43)/2)/(1+$A8)^5-Historical!$G$24)/DCF!$B$18 -> 24.588418 | C8: =(Projections_TL!$B$33/(1+$A8)^1+Projections_TL!$C$33/(1+$A8)^2+Projections_TL!$D$33/(1+$A8)^3+Projections_TL!$E$33/(1+$A8)^4+Projections_TL!$F$33/(1+$A8)^5+((Projections_TL!$F$33*(1+C$5)/($A8-C$5)+Projections_TL!$F$20*Projections_TL!$B$43)/2)/(1+$A8)^5-Historical!$G$24)/DCF!$B$18 -> 24.884237 | D8: =(Projections_TL!$B$33/(1+$A8)^1+Projections_TL!$C$33/(1+$A8)^2+Projections_TL!$D$33/(1+$A8)^3+Projections_TL!$E$33/(1+$A8)^4+Projections_TL!$F$33/(1+$A8)^5+((Projections_TL!$F$33*(1+D$5)/($A8-D$5)+Projections_TL!$F$20*Projections_TL!$B$43)/2)/(1+$A8)^5-Historical!$G$24)/DCF!$B$18 -> 25.204048 | E8: =(Projections_TL!$B$33/(1+$A8)^1+Projections_TL!$C$33/(1+$A8)^2+Projections_TL!$D$33/(1+$A8)^3+Projections_TL!$E$33/(1+$A8)^4+Projections_TL!$F$33/(1+$A8)^5+((Projections_TL!$F$33*(1+E$5)/($A8-E$5)+Projections_TL!$F$20*Projections_TL!$B$43)/2)/(1+$A8)^5-Historical!$G$24)/DCF!$B$18 -> 25.550893 | F8: =(Projections_TL!$B$33/(1+$A8)^1+Projections_TL!$C$33/(1+$A8)^2+Projections_TL!$D$33/(1+$A8)^3+Projections_TL!$E$33/(1+$A8)^4+Projections_TL!$F$33/(1+$A8)^5+((Projections_TL!$F$33*(1+F$5)/($A8-F$5)+Projections_TL!$F$20*Projections_TL!$B$43)/2)/(1+$A8)^5-Historical!$G$24)/DCF!$B$18 -> 25.92835
A9: 0.16 | B9: =(Projections_TL!$B$33/(1+$A9)^1+Projections_TL!$C$33/(1+$A9)^2+Projections_TL!$D$33/(1+$A9)^3+Projections_TL!$E$33/(1+$A9)^4+Projections_TL!$F$33/(1+$A9)^5+((Projections_TL!$F$33*(1+B$5)/($A9-B$5)+Projections_TL!$F$20*Projections_TL!$B$43)/2)/(1+$A9)^5-Historical!$G$24)/DCF!$B$18 -> 22.64702 | C9: =(Projections_TL!$B$33/(1+$A9)^1+Projections_TL!$C$33/(1+$A9)^2+Projections_TL!$D$33/(1+$A9)^3+Projections_TL!$E$33/(1+$A9)^4+Projections_TL!$F$33/(1+$A9)^5+((Projections_TL!$F$33*(1+C$5)/($A9-C$5)+Projections_TL!$F$20*Projections_TL!$B$43)/2)/(1+$A9)^5-Historical!$G$24)/DCF!$B$18 -> 22.886339 | D9: =(Projections_TL!$B$33/(1+$A9)^1+Projections_TL!$C$33/(1+$A9)^2+Projections_TL!$D$33/(1+$A9)^3+Projections_TL!$E$33/(1+$A9)^4+Projections_TL!$F$33/(1+$A9)^5+((Projections_TL!$F$33*(1+D$5)/($A9-D$5)+Projections_TL!$F$20*Projections_TL!$B$43)/2)/(1+$A9)^5-Historical!$G$24)/DCF!$B$18 -> 23.143385 | E9: =(Projections_TL!$B$33/(1+$A9)^1+Projections_TL!$C$33/(1+$A9)^2+Projections_TL!$D$33/(1+$A9)^3+Projections_TL!$E$33/(1+$A9)^4+Projections_TL!$F$33/(1+$A9)^5+((Projections_TL!$F$33*(1+E$5)/($A9-E$5)+Projections_TL!$F$20*Projections_TL!$B$43)/2)/(1+$A9)^5-Historical!$G$24)/DCF!$B$18 -> 23.420204 | F9: =(Projections_TL!$B$33/(1+$A9)^1+Projections_TL!$C$33/(1+$A9)^2+Projections_TL!$D$33/(1+$A9)^3+Projections_TL!$E$33/(1+$A9)^4+Projections_TL!$F$33/(1+$A9)^5+((Projections_TL!$F$33*(1+F$5)/($A9-F$5)+Projections_TL!$F$20*Projections_TL!$B$43)/2)/(1+$A9)^5-Historical!$G$24)/DCF!$B$18 -> 23.719168
A10: 0.17 | B10: =(Projections_TL!$B$33/(1+$A10)^1+Projections_TL!$C$33/(1+$A10)^2+Projections_TL!$D$33/(1+$A10)^3+Projections_TL!$E$33/(1+$A10)^4+Projections_TL!$F$33/(1+$A10)^5+((Projections_TL!$F$33*(1+B$5)/($A10-B$5)+Projections_TL!$F$20*Projections_TL!$B$43)/2)/(1+$A10)^5-Historical!$G$24)/DCF!$B$18 -> 21.151127 | C10: =(Projections_TL!$B$33/(1+$A10)^1+Projections_TL!$C$33/(1+$A10)^2+Projections_TL!$D$33/(1+$A10)^3+Projections_TL!$E$33/(1+$A10)^4+Projections_TL!$F$33/(1+$A10)^5+((Projections_TL!$F$33*(1+C$5)/($A10-C$5)+Projections_TL!$F$20*Projections_TL!$B$43)/2)/(1+$A10)^5-Historical!$G$24)/DCF!$B$18 -> 21.353028 | D10: =(Projections_TL!$B$33/(1+$A10)^1+Projections_TL!$C$33/(1+$A10)^2+Projections_TL!$D$33/(1+$A10)^3+Projections_TL!$E$33/(1+$A10)^4+Projections_TL!$F$33/(1+$A10)^5+((Projections_TL!$F$33*(1+D$5)/($A10-D$5)+Projections_TL!$F$20*Projections_TL!$B$43)/2)/(1+$A10)^5-Historical!$G$24)/DCF!$B$18 -> 21.568853 | E10: =(Projections_TL!$B$33/(1+$A10)^1+Projections_TL!$C$33/(1+$A10)^2+Projections_TL!$D$33/(1+$A10)^3+Projections_TL!$E$33/(1+$A10)^4+Projections_TL!$F$33/(1+$A10)^5+((Projections_TL!$F$33*(1+E$5)/($A10-E$5)+Projections_TL!$F$20*Projections_TL!$B$43)/2)/(1+$A10)^5-Historical!$G$24)/DCF!$B$18 -> 21.800094 | F10: =(Projections_TL!$B$33/(1+$A10)^1+Projections_TL!$C$33/(1+$A10)^2+Projections_TL!$D$33/(1+$A10)^3+Projections_TL!$E$33/(1+$A10)^4+Projections_TL!$F$33/(1+$A10)^5+((Projections_TL!$F$33*(1+F$5)/($A10-F$5)+Projections_TL!$F$20*Projections_TL!$B$43)/2)/(1+$A10)^5-Historical!$G$24)/DCF!$B$18 -> 22.048464

Sheet Comps
A1: EREGL — Comparable Companies Analysis
A2: As of 04 May 2026 | Mn local currency
A4: Company | B4: Country | C4: Mkt Cap | D4: Net Debt | E4: EV | F4: Revenue | G4: EBITDA | H4: EV/EBITDA | I4: EV/Sales
A5: KRDMD | B5: TR | C5: 30491 | D5: 3948 | E5: =C5+D5 -> 34439 | F5: 59565 | G5: 5968 | H5: =E5/G5 -> 5.7706099 | I5: =E5/F5 -> 0.5781751
A6: Nucor | B6: US | C6: 51480 | D6: 4640 | E6: =C6+D6 -> 56120 | F6: 34160 | G6: 4990 | H6: =E6/G6 -> 11.246493 | I6: =E6/F6 -> 1.6428571
A7: Arcelor Mittal | B7: LU | C7: 42160 | D7: 7900 | E7: =C7+D7 -> 50060 | F7: 61352 | G7: 6541 | H7: =E7/G7 -> 7.653264 | I7: =E7/F7 -> 0.81594732
A9: Peer Median | H9: =MEDIAN(H5:H7) -> 7.653264 | I9: =MEDIAN(I5:I7) -> 0.81594732
A10: Peer Mean | H10: =AVERAGE(H5:H7) -> 8.2234556 | I10: =AVERAGE(I5:I7) -> 1.0123265
A12: EREGL (target) | B12: TR | C12: 245840 | D12: 42800 | E12: =C12+D12 -> 288640 | F12: 208910 | G12: 20451 | H12: =E12/G12 -> 14.113735 | I12: =E12/F12 -> 1.3816476
A13: Premium / (Disc) % | H13: =H12/H9-1 -> 0.84414587 | I13: =I12/I9-1 -> 0.6933049
A15: Implied Valuation
A16: Method 1: EV/EBITDA Multiple
A17: Peer Median EV/EBITDA | B17: =H9 -> 7.653264
A18: × EREGL EBITDA 2025 | B18: =G12 -> 20451
A19: Implied EV | B19: =B17*B18 -> 156516.9
A20: (-) Net Debt | B20: =D12 -> 42800
A21: Implied Equity | B21: =B19-B20 -> 113716.9
A22: Shares Outstanding (mn) | B22: 7000
A23: Implied Price (TL) | B23: =B21/B22 -> 16.245272
A25: Method 2: EV/Sales Multiple
A26: Peer Median EV/Sales | B26: =I9 -> 0.81594732
A27: × EREGL Revenue 2025 | B27: =F12 -> 208910
A28: Implied EV | B28: =B26*B27 -> 170459.55
A29: (-) Net Debt | B29: =D12 -> 42800
A30: Implied Equity | B30: =B28-B29 -> 127659.55
A31: Shares Outstanding (mn) | B31: 7000
A32: Implied Price (TL) | B32: =B30/B31 -> 18.237079
A34: Final Output
A35: Average Implied Price (TL) | B35: =AVERAGE(B23,B32) -> 17.241176
A36: Current Market Price (TL) | B36: =DCF!B20 -> 35.12
A37: Upside / (Downside) % | B37: =B35/B36-1 -> -0.50907815
